[2025-04-05T15:55:50.852+0000] {local_task_job_runner.py:120} INFO - ::group::Pre task execution logs
[2025-04-05T15:55:50.891+0000] {taskinstance.py:2076} INFO - Dependencies all met for dep_context=non-requeueable deps ti=<TaskInstance: run_streamlit.run_streamlit_app manual__2025-04-05T15:55:49.866629+00:00 [queued]>
[2025-04-05T15:55:50.900+0000] {taskinstance.py:2076} INFO - Dependencies all met for dep_context=requeueable deps ti=<TaskInstance: run_streamlit.run_streamlit_app manual__2025-04-05T15:55:49.866629+00:00 [queued]>
[2025-04-05T15:55:50.901+0000] {taskinstance.py:2306} INFO - Starting attempt 1 of 2
[2025-04-05T15:55:50.915+0000] {taskinstance.py:2330} INFO - Executing <Task(BashOperator): run_streamlit_app> on 2025-04-05 15:55:49.866629+00:00
[2025-04-05T15:55:50.922+0000] {logging_mixin.py:188} WARNING - /home/***/.local/lib/python3.12/site-packages/***/task/task_runner/standard_task_runner.py:61 DeprecationWarning: This process (pid=616) is multi-threaded, use of fork() may lead to deadlocks in the child.
[2025-04-05T15:55:50.923+0000] {standard_task_runner.py:63} INFO - Started process 617 to run task
[2025-04-05T15:55:50.922+0000] {standard_task_runner.py:90} INFO - Running: ['***', 'tasks', 'run', 'run_streamlit', 'run_streamlit_app', 'manual__2025-04-05T15:55:49.866629+00:00', '--job-id', '10', '--raw', '--subdir', 'DAGS_FOLDER/run_streamlit.py', '--cfg-path', '/tmp/tmp4faosbn6']
[2025-04-05T15:55:50.924+0000] {standard_task_runner.py:91} INFO - Job 10: Subtask run_streamlit_app
[2025-04-05T15:55:50.942+0000] {logging_mixin.py:188} WARNING - /home/***/.local/lib/python3.12/site-packages/***/settings.py:195 DeprecationWarning: The sql_alchemy_conn option in [core] has been moved to the sql_alchemy_conn option in [database] - the old setting has been used, but please update your config.
[2025-04-05T15:55:50.982+0000] {task_command.py:426} INFO - Running <TaskInstance: run_streamlit.run_streamlit_app manual__2025-04-05T15:55:49.866629+00:00 [running]> on host a4017603cc0b
[2025-04-05T15:55:51.083+0000] {taskinstance.py:2648} INFO - Exporting env vars: AIRFLOW_CTX_DAG_OWNER='***' AIRFLOW_CTX_DAG_ID='run_streamlit' AIRFLOW_CTX_TASK_ID='run_streamlit_app' AIRFLOW_CTX_EXECUTION_DATE='2025-04-05T15:55:49.866629+00:00' AIRFLOW_CTX_TRY_NUMBER='1' AIRFLOW_CTX_DAG_RUN_ID='manual__2025-04-05T15:55:49.866629+00:00'
[2025-04-05T15:55:51.084+0000] {taskinstance.py:430} INFO - ::endgroup::
[2025-04-05T15:55:51.100+0000] {subprocess.py:63} INFO - Tmp dir root location: /tmp
[2025-04-05T15:55:51.101+0000] {subprocess.py:75} INFO - Running command: ['/usr/bin/bash', '-c', 'streamlit run visualization/dashboard.py --server.port 8501 --server.address=0.0.0.0']
[2025-04-05T15:55:51.109+0000] {subprocess.py:86} INFO - Output:
[2025-04-05T15:55:52.379+0000] {subprocess.py:93} INFO - Usage: streamlit run [OPTIONS] TARGET [ARGS]...
[2025-04-05T15:55:52.380+0000] {subprocess.py:93} INFO - Try 'streamlit run --help' for help.
[2025-04-05T15:55:52.380+0000] {subprocess.py:93} INFO - 
[2025-04-05T15:55:52.381+0000] {subprocess.py:93} INFO - Error: Invalid value: File does not exist: visualization/dashboard.py
[2025-04-05T15:55:52.434+0000] {subprocess.py:97} INFO - Command exited with return code 2
[2025-04-05T15:55:52.436+0000] {taskinstance.py:441} INFO - ::group::Post task execution logs
[2025-04-05T15:55:52.447+0000] {taskinstance.py:2905} ERROR - Task failed with exception
Traceback (most recent call last):
  File "/home/airflow/.local/lib/python3.12/site-packages/airflow/models/taskinstance.py", line 465, in _execute_task
    result = _execute_callable(context=context, **execute_callable_kwargs)
             ^^^^^^^^^^^^^^^^^^^^^^^^^^^^^^^^^^^^^^^^^^^^^^^^^^^^^^^^^^^^^
  File "/home/airflow/.local/lib/python3.12/site-packages/airflow/models/taskinstance.py", line 432, in _execute_callable
    return execute_callable(context=context, **execute_callable_kwargs)
           ^^^^^^^^^^^^^^^^^^^^^^^^^^^^^^^^^^^^^^^^^^^^^^^^^^^^^^^^^^^^
  File "/home/airflow/.local/lib/python3.12/site-packages/airflow/models/baseoperator.py", line 401, in wrapper
    return func(self, *args, **kwargs)
           ^^^^^^^^^^^^^^^^^^^^^^^^^^^
  File "/home/airflow/.local/lib/python3.12/site-packages/airflow/operators/bash.py", line 243, in execute
    raise AirflowException(
airflow.exceptions.AirflowException: Bash command failed. The command returned a non-zero exit code 2.
[2025-04-05T15:55:52.452+0000] {taskinstance.py:1206} INFO - Marking task as UP_FOR_RETRY. dag_id=run_streamlit, task_id=run_streamlit_app, run_id=manual__2025-04-05T15:55:49.866629+00:00, execution_date=20250405T155549, start_date=20250405T155550, end_date=20250405T155552
[2025-04-05T15:55:52.462+0000] {standard_task_runner.py:110} ERROR - Failed to execute job 10 for task run_streamlit_app (Bash command failed. The command returned a non-zero exit code 2.; 617)
[2025-04-05T15:55:52.486+0000] {local_task_job_runner.py:240} INFO - Task exited with return code 1
[2025-04-05T15:55:52.522+0000] {taskinstance.py:3503} INFO - 0 downstream tasks scheduled from follow-on schedule check
[2025-04-05T15:55:52.525+0000] {local_task_job_runner.py:222} INFO - ::endgroup::
