[2025-04-05T16:00:53.036+0000] {local_task_job_runner.py:120} INFO - ::group::Pre task execution logs
[2025-04-05T16:00:53.107+0000] {taskinstance.py:2076} INFO - Dependencies all met for dep_context=non-requeueable deps ti=<TaskInstance: run_streamlit.run_streamlit_app manual__2025-04-05T15:55:49.866629+00:00 [queued]>
[2025-04-05T16:00:53.123+0000] {taskinstance.py:2076} INFO - Dependencies all met for dep_context=requeueable deps ti=<TaskInstance: run_streamlit.run_streamlit_app manual__2025-04-05T15:55:49.866629+00:00 [queued]>
[2025-04-05T16:00:53.124+0000] {taskinstance.py:2306} INFO - Starting attempt 2 of 2
[2025-04-05T16:00:53.149+0000] {taskinstance.py:2330} INFO - Executing <Task(BashOperator): run_streamlit_app> on 2025-04-05 15:55:49.866629+00:00
[2025-04-05T16:00:53.160+0000] {logging_mixin.py:188} WARNING - /home/***/.local/lib/python3.12/site-packages/***/task/task_runner/standard_task_runner.py:61 DeprecationWarning: This process (pid=988) is multi-threaded, use of fork() may lead to deadlocks in the child.
[2025-04-05T16:00:53.162+0000] {standard_task_runner.py:63} INFO - Started process 992 to run task
[2025-04-05T16:00:53.160+0000] {standard_task_runner.py:90} INFO - Running: ['***', 'tasks', 'run', 'run_streamlit', 'run_streamlit_app', 'manual__2025-04-05T15:55:49.866629+00:00', '--job-id', '11', '--raw', '--subdir', 'DAGS_FOLDER/run_streamlit.py', '--cfg-path', '/tmp/tmpxdtglz58']
[2025-04-05T16:00:53.163+0000] {standard_task_runner.py:91} INFO - Job 11: Subtask run_streamlit_app
[2025-04-05T16:00:53.192+0000] {logging_mixin.py:188} WARNING - /home/***/.local/lib/python3.12/site-packages/***/settings.py:195 DeprecationWarning: The sql_alchemy_conn option in [core] has been moved to the sql_alchemy_conn option in [database] - the old setting has been used, but please update your config.
[2025-04-05T16:00:53.255+0000] {task_command.py:426} INFO - Running <TaskInstance: run_streamlit.run_streamlit_app manual__2025-04-05T15:55:49.866629+00:00 [running]> on host a4017603cc0b
[2025-04-05T16:00:53.371+0000] {taskinstance.py:2648} INFO - Exporting env vars: AIRFLOW_CTX_DAG_OWNER='***' AIRFLOW_CTX_DAG_ID='run_streamlit' AIRFLOW_CTX_TASK_ID='run_streamlit_app' AIRFLOW_CTX_EXECUTION_DATE='2025-04-05T15:55:49.866629+00:00' AIRFLOW_CTX_TRY_NUMBER='2' AIRFLOW_CTX_DAG_RUN_ID='manual__2025-04-05T15:55:49.866629+00:00'
[2025-04-05T16:00:53.372+0000] {taskinstance.py:430} INFO - ::endgroup::
[2025-04-05T16:00:53.391+0000] {subprocess.py:63} INFO - Tmp dir root location: /tmp
[2025-04-05T16:00:53.392+0000] {subprocess.py:75} INFO - Running command: ['/usr/bin/bash', '-c', 'streamlit run visualization/dashboard.py --server.port 8501 --server.address=0.0.0.0']
[2025-04-05T16:00:53.403+0000] {subprocess.py:86} INFO - Output:
[2025-04-05T16:00:54.496+0000] {subprocess.py:93} INFO - Usage: streamlit run [OPTIONS] TARGET [ARGS]...
[2025-04-05T16:00:54.497+0000] {subprocess.py:93} INFO - Try 'streamlit run --help' for help.
[2025-04-05T16:00:54.497+0000] {subprocess.py:93} INFO - 
[2025-04-05T16:00:54.498+0000] {subprocess.py:93} INFO - Error: Invalid value: File does not exist: visualization/dashboard.py
[2025-04-05T16:00:54.556+0000] {subprocess.py:97} INFO - Command exited with return code 2
[2025-04-05T16:00:54.557+0000] {taskinstance.py:441} INFO - ::group::Post task execution logs
[2025-04-05T16:00:54.569+0000] {taskinstance.py:2905} ERROR - Task failed with exception
Traceback (most recent call last):
  File "/home/airflow/.local/lib/python3.12/site-packages/airflow/models/taskinstance.py", line 465, in _execute_task
    result = _execute_callable(context=context, **execute_callable_kwargs)
             ^^^^^^^^^^^^^^^^^^^^^^^^^^^^^^^^^^^^^^^^^^^^^^^^^^^^^^^^^^^^^
  File "/home/airflow/.local/lib/python3.12/site-packages/airflow/models/taskinstance.py", line 432, in _execute_callable
    return execute_callable(context=context, **execute_callable_kwargs)
           ^^^^^^^^^^^^^^^^^^^^^^^^^^^^^^^^^^^^^^^^^^^^^^^^^^^^^^^^^^^^
  File "/home/airflow/.local/lib/python3.12/site-packages/airflow/models/baseoperator.py", line 401, in wrapper
    return func(self, *args, **kwargs)
           ^^^^^^^^^^^^^^^^^^^^^^^^^^^
  File "/home/airflow/.local/lib/python3.12/site-packages/airflow/operators/bash.py", line 243, in execute
    raise AirflowException(
airflow.exceptions.AirflowException: Bash command failed. The command returned a non-zero exit code 2.
[2025-04-05T16:00:54.573+0000] {taskinstance.py:1206} INFO - Marking task as FAILED. dag_id=run_streamlit, task_id=run_streamlit_app, run_id=manual__2025-04-05T15:55:49.866629+00:00, execution_date=20250405T155549, start_date=20250405T160053, end_date=20250405T160054
[2025-04-05T16:00:54.594+0000] {standard_task_runner.py:110} ERROR - Failed to execute job 11 for task run_streamlit_app (Bash command failed. The command returned a non-zero exit code 2.; 992)
[2025-04-05T16:00:54.634+0000] {local_task_job_runner.py:240} INFO - Task exited with return code 1
[2025-04-05T16:00:54.651+0000] {taskinstance.py:3503} INFO - 0 downstream tasks scheduled from follow-on schedule check
[2025-04-05T16:00:54.653+0000] {local_task_job_runner.py:222} INFO - ::endgroup::
