2025-04-08 21:12:07 - urllib3.connectionpool - WARNING - Retrying (Retry(total=4, connect=None, read=None, redirect=None, status=None)) after connection broken by 'NameResolutionError("<urllib3.connection.HTTPConnection object at 0x000001511595E050>: Failed to resolve 'minio' ([Errno 11001] getaddrinfo failed)")': /
2025-04-08 21:12:09 - urllib3.connectionpool - WARNING - Retrying (Retry(total=3, connect=None, read=None, redirect=None, status=None)) after connection broken by 'NameResolutionError("<urllib3.connection.HTTPConnection object at 0x0000015115983E90>: Failed to resolve 'minio' ([Errno 11001] getaddrinfo failed)")': /
2025-04-08 21:12:10 - urllib3.connectionpool - WARNING - Retrying (Retry(total=2, connect=None, read=None, redirect=None, status=None)) after connection broken by 'NameResolutionError("<urllib3.connection.HTTPConnection object at 0x000001511599A1D0>: Failed to resolve 'minio' ([Errno 11001] getaddrinfo failed)")': /
2025-04-08 21:12:13 - urllib3.connectionpool - WARNING - Retrying (Retry(total=1, connect=None, read=None, redirect=None, status=None)) after connection broken by 'NameResolutionError("<urllib3.connection.HTTPConnection object at 0x000001511599AD10>: Failed to resolve 'minio' ([Errno 11001] getaddrinfo failed)")': /
2025-04-08 21:12:17 - urllib3.connectionpool - WARNING - Retrying (Retry(total=0, connect=None, read=None, redirect=None, status=None)) after connection broken by 'NameResolutionError("<urllib3.connection.HTTPConnection object at 0x000001511599B850>: Failed to resolve 'minio' ([Errno 11001] getaddrinfo failed)")': /
2025-04-08 21:12:18 - init_minio - ERROR - Error connecting to Minio client: HTTPConnectionPool(host='minio', port=9000): Max retries exceeded with url: / (Caused by NameResolutionError("<urllib3.connection.HTTPConnection object at 0x00000151159AC3D0>: Failed to resolve 'minio' ([Errno 11001] getaddrinfo failed)"))
2025-04-08 21:36:15 - __main__ - INFO - Last load date: 2021-01-03
2025-04-08 21:36:15 - __main__ - INFO - Next load date: 2021-01-04
2025-04-08 21:36:51 - __main__ - INFO - Last load date: 2021-01-03
2025-04-08 21:36:51 - __main__ - INFO - Next load date: 2021-01-04
2025-04-09 09:15:07 - __main__ - INFO - Last load date: 2021-01-03
2025-04-09 09:15:07 - __main__ - INFO - Next load date: 2021-01-04
2025-04-09 09:38:02 - scripts.extractor - INFO - Last load date: 2021-01-03
2025-04-09 09:38:02 - scripts.extractor - INFO - Next load date: 2021-01-04
2025-04-09 10:47:27 - urllib3.connectionpool - WARNING - Retrying (Retry(total=4, connect=None, read=None, redirect=None, status=None)) after connection broken by 'NameResolutionError("<urllib3.connection.HTTPConnection object at 0x00000159FCD6E110>: Failed to resolve 'minio' ([Errno 11001] getaddrinfo failed)")': /
2025-04-09 10:47:29 - urllib3.connectionpool - WARNING - Retrying (Retry(total=3, connect=None, read=None, redirect=None, status=None)) after connection broken by 'NameResolutionError("<urllib3.connection.HTTPConnection object at 0x00000159FCD85710>: Failed to resolve 'minio' ([Errno 11001] getaddrinfo failed)")': /
2025-04-09 10:47:31 - urllib3.connectionpool - WARNING - Retrying (Retry(total=2, connect=None, read=None, redirect=None, status=None)) after connection broken by 'NameResolutionError("<urllib3.connection.HTTPConnection object at 0x00000159FCDB3DD0>: Failed to resolve 'minio' ([Errno 11001] getaddrinfo failed)")': /
2025-04-09 10:47:33 - urllib3.connectionpool - WARNING - Retrying (Retry(total=1, connect=None, read=None, redirect=None, status=None)) after connection broken by 'NameResolutionError("<urllib3.connection.HTTPConnection object at 0x00000159FCDB8990>: Failed to resolve 'minio' ([Errno 11001] getaddrinfo failed)")': /
2025-04-09 10:47:37 - urllib3.connectionpool - WARNING - Retrying (Retry(total=0, connect=None, read=None, redirect=None, status=None)) after connection broken by 'NameResolutionError("<urllib3.connection.HTTPConnection object at 0x00000159FCDB94D0>: Failed to resolve 'minio' ([Errno 11001] getaddrinfo failed)")': /
2025-04-09 10:47:38 - init_minio - ERROR - Error connecting to Minio client: HTTPConnectionPool(host='minio', port=9000): Max retries exceeded with url: / (Caused by NameResolutionError("<urllib3.connection.HTTPConnection object at 0x00000159FCDBA010>: Failed to resolve 'minio' ([Errno 11001] getaddrinfo failed)"))
2025-04-09 10:50:03 - urllib3.connectionpool - WARNING - Retrying (Retry(total=4, connect=None, read=None, redirect=None, status=None)) after connection broken by 'NameResolutionError("<urllib3.connection.HTTPConnection object at 0x000001C667E68AD0>: Failed to resolve 'minio' ([Errno 11001] getaddrinfo failed)")': /
2025-04-09 10:50:04 - urllib3.connectionpool - WARNING - Retrying (Retry(total=3, connect=None, read=None, redirect=None, status=None)) after connection broken by 'NameResolutionError("<urllib3.connection.HTTPConnection object at 0x000001C668B789D0>: Failed to resolve 'minio' ([Errno 11001] getaddrinfo failed)")': /
2025-04-09 10:50:06 - urllib3.connectionpool - WARNING - Retrying (Retry(total=2, connect=None, read=None, redirect=None, status=None)) after connection broken by 'NameResolutionError("<urllib3.connection.HTTPConnection object at 0x000001C668B94F50>: Failed to resolve 'minio' ([Errno 11001] getaddrinfo failed)")': /
2025-04-09 10:50:09 - urllib3.connectionpool - WARNING - Retrying (Retry(total=1, connect=None, read=None, redirect=None, status=None)) after connection broken by 'NameResolutionError("<urllib3.connection.HTTPConnection object at 0x000001C668B95AD0>: Failed to resolve 'minio' ([Errno 11001] getaddrinfo failed)")': /
2025-04-09 10:50:13 - urllib3.connectionpool - WARNING - Retrying (Retry(total=0, connect=None, read=None, redirect=None, status=None)) after connection broken by 'NameResolutionError("<urllib3.connection.HTTPConnection object at 0x000001C668B96610>: Failed to resolve 'minio' ([Errno 11001] getaddrinfo failed)")': /
2025-04-09 10:50:14 - init_minio - ERROR - Error connecting to Minio client: HTTPConnectionPool(host='minio', port=9000): Max retries exceeded with url: / (Caused by NameResolutionError("<urllib3.connection.HTTPConnection object at 0x000001C668B97150>: Failed to resolve 'minio' ([Errno 11001] getaddrinfo failed)"))
2025-04-09 10:50:23 - urllib3.connectionpool - WARNING - Retrying (Retry(total=4, connect=None, read=None, redirect=None, status=None)) after connection broken by 'NameResolutionError("<urllib3.connection.HTTPConnection object at 0x0000023AD5C34150>: Failed to resolve 'minio' ([Errno 11001] getaddrinfo failed)")': /
2025-04-09 10:50:25 - urllib3.connectionpool - WARNING - Retrying (Retry(total=3, connect=None, read=None, redirect=None, status=None)) after connection broken by 'NameResolutionError("<urllib3.connection.HTTPConnection object at 0x0000023AD5C44F10>: Failed to resolve 'minio' ([Errno 11001] getaddrinfo failed)")': /
2025-04-09 10:50:27 - urllib3.connectionpool - WARNING - Retrying (Retry(total=2, connect=None, read=None, redirect=None, status=None)) after connection broken by 'NameResolutionError("<urllib3.connection.HTTPConnection object at 0x0000023AD5C4A310>: Failed to resolve 'minio' ([Errno 11001] getaddrinfo failed)")': /
2025-04-09 10:50:29 - urllib3.connectionpool - WARNING - Retrying (Retry(total=1, connect=None, read=None, redirect=None, status=None)) after connection broken by 'NameResolutionError("<urllib3.connection.HTTPConnection object at 0x0000023AD5C4AE90>: Failed to resolve 'minio' ([Errno 11001] getaddrinfo failed)")': /
2025-04-09 10:50:33 - urllib3.connectionpool - WARNING - Retrying (Retry(total=0, connect=None, read=None, redirect=None, status=None)) after connection broken by 'NameResolutionError("<urllib3.connection.HTTPConnection object at 0x0000023AD5C4B9D0>: Failed to resolve 'minio' ([Errno 11001] getaddrinfo failed)")': /
2025-04-09 10:50:34 - init_minio - ERROR - Error connecting to Minio client: HTTPConnectionPool(host='minio', port=9000): Max retries exceeded with url: / (Caused by NameResolutionError("<urllib3.connection.HTTPConnection object at 0x0000023AD5C64550>: Failed to resolve 'minio' ([Errno 11001] getaddrinfo failed)"))
2025-04-09 10:51:16 - __main__ - ERROR - Error loading data to DuckDB: IO Error: No files found that match the pattern "temp/bitcoin-2024-01-04"
2025-04-09 10:52:35 - __main__ - ERROR - Error loading data to DuckDB: IO Error: No files found that match the pattern "temp\bitcoin-2024-01-04"
2025-04-09 10:54:44 - __main__ - ERROR - Error loading data to DuckDB: IO Error: No files found that match the pattern "temp\bitcoin-2024-01-04.csv"
2025-04-09 11:02:00 - __main__ - ERROR - Error loading data to DuckDB: IO Error: No files found that match the pattern "temp\bitcoin-2024-01-04.csv"
2025-04-09 11:02:20 - __main__ - ERROR - Error loading data to DuckDB: IO Error: No files found that match the pattern "temp\bitcoin-2024-01-04.csv"
2025-04-09 11:03:09 - __main__ - ERROR - Error loading data to DuckDB: Conversion Error: CSV Error on Line: 2
Original Line: 32872.7692465489242831,1609718400000,2021-01-04T00:00:00.000Z,18589737.0000000000000000
Error when converting column "date". Could not convert string "2021-01-04T00:00:00.000Z" to 'DOUBLE'

Column date is being converted as type DOUBLE
This type was auto-detected from the CSV file.
Possible solutions:
* Override the type for this column manually by setting the type explicitly, e.g. types={'date': 'VARCHAR'}
* Set the sample size to a larger value to enable the auto-detection to scan more values, e.g. sample_size=-1
* Use a COPY statement to automatically derive types from an existing table.
* Check whether the null string value is set correctly (e.g., nullstr = 'N/A')

  file = temp\bitcoin-2021-01-04
  delimiter = , (Auto-Detected)
  quote = \0 (Auto-Detected)
  escape = \0 (Auto-Detected)
  new_line = \r\n (Auto-Detected)
  header = true (Set By User)
  skip_rows = 0 (Auto-Detected)
  comment = \0 (Auto-Detected)
  strict_mode = true (Auto-Detected)
  date_format =  (Auto-Detected)
  timestamp_format =  (Auto-Detected)
  null_padding = 0
  sample_size = 20480
  ignore_errors = false
  all_varchar = 0


2025-04-09 11:11:53 - __main__ - ERROR - Error loading data to DuckDB: Binder Error: No function matches the given name and argument types 'replace(TIMESTAMP, STRING_LITERAL, STRING_LITERAL)'. You might need to add explicit type casts.
	Candidate functions:
	replace(VARCHAR, VARCHAR, VARCHAR) -> VARCHAR


LINE 6:                 CAST(REPLACE(date, 'T', ' ') AS TIMESTAMP) AS date,
                             ^
2025-04-09 11:13:04 - __main__ - ERROR - Error loading data to DuckDB: Conversion Error: Unimplemented type for cast (TIMESTAMP -> DOUBLE)

LINE 6:                 CAST(REPLACE(CAST(date AS VARCHAR), 'T', ' ') AS TIMESTAMP...
                        ^
2025-04-09 11:17:53 - __main__ - INFO - Data loaded to DuckDB successfully
